#include <iostream>
#include <stdexcept>

int main() {
    try {
        int value = -1;
        if (value < 0) {
            throw std::runtime_error("Value cannot be negative."); // Throw a runtime_error
        } else if (value == 0) {
            throw std::logic_error("Value cannot be zero."); // Throw a logic_error
        } else {
            std::cout << "Value: " << value << std::endl;
        }
    } catch (const std::runtime_error& e) {
        std::cerr << "Caught runtime_error: " << e.what() << std::endl;
    } catch (const std::logic_error& e) {
        std::cerr << "Caught logic_error: " << e.what() << std::endl;
    } catch (...) {
        std::cerr << "Caught unknown exception." << std::endl;
    }

    return 0;
}
